2014-06-02 19:03:20,152 [ERROR] django.request: Internal Server Error: /articles/all
Traceback (most recent call last):
  File "/home/damon/Documents/Python/django-damon/local/lib/python2.7/site-packages/Django-1.6.4-py2.7.egg/django/core/handlers/base.py", line 90, in get_response
    response = middleware_method(request)
  File "/home/damon/Documents/Python/django-damon/local/lib/python2.7/site-packages/Django-1.6.4-py2.7.egg/django/middleware/common.py", line 71, in process_request
    if (not urlresolvers.is_valid_path(request.path_info, urlconf) and
  File "/home/damon/Documents/Python/django-damon/local/lib/python2.7/site-packages/Django-1.6.4-py2.7.egg/django/core/urlresolvers.py", line 596, in is_valid_path
    resolve(path, urlconf)
  File "/home/damon/Documents/Python/django-damon/local/lib/python2.7/site-packages/Django-1.6.4-py2.7.egg/django/core/urlresolvers.py", line 476, in resolve
    return get_resolver(urlconf).resolve(path)
  File "/home/damon/Documents/Python/django-damon/local/lib/python2.7/site-packages/Django-1.6.4-py2.7.egg/django/core/urlresolvers.py", line 337, in resolve
    for pattern in self.url_patterns:
  File "/home/damon/Documents/Python/django-damon/local/lib/python2.7/site-packages/Django-1.6.4-py2.7.egg/django/core/urlresolvers.py", line 365, in url_patterns
    patterns = getattr(self.urlconf_module, "urlpatterns", self.urlconf_module)
  File "/home/damon/Documents/Python/django-damon/local/lib/python2.7/site-packages/Django-1.6.4-py2.7.egg/django/core/urlresolvers.py", line 360, in urlconf_module
    self._urlconf_module = import_module(self.urlconf_name)
  File "/home/damon/Documents/Python/django-damon/local/lib/python2.7/site-packages/Django-1.6.4-py2.7.egg/django/utils/importlib.py", line 40, in import_module
    __import__(name)
  File "/home/damon/Project/TenniSoda/TenniSoda/urls.py", line 4, in <module>
    admin.autodiscover()
  File "/home/damon/Documents/Python/django-damon/local/lib/python2.7/site-packages/Django-1.6.4-py2.7.egg/django/contrib/admin/__init__.py", line 29, in autodiscover
    import_module('%s.admin' % app)
  File "/home/damon/Documents/Python/django-damon/local/lib/python2.7/site-packages/Django-1.6.4-py2.7.egg/django/utils/importlib.py", line 40, in import_module
    __import__(name)
  File "/home/damon/Project/TenniSoda/account/admin.py", line 10, in <module>
    class UserCreationForm(forms.ModelForm):
  File "/home/damon/Documents/Python/django-damon/local/lib/python2.7/site-packages/Django-1.6.4-py2.7.egg/django/forms/models.py", line 261, in __new__
    raise TypeError(msg)
TypeError: UserCreationForm.Meta.fields cannot be a string. Did you mean to type: ('email',)?
2014-06-02 19:03:21,976 [ERROR] django.request: Internal Server Error: /
Traceback (most recent call last):
  File "/home/damon/Documents/Python/django-damon/local/lib/python2.7/site-packages/Django-1.6.4-py2.7.egg/django/core/handlers/base.py", line 101, in get_response
    resolver_match = resolver.resolve(request.path_info)
  File "/home/damon/Documents/Python/django-damon/local/lib/python2.7/site-packages/Django-1.6.4-py2.7.egg/django/core/urlresolvers.py", line 337, in resolve
    for pattern in self.url_patterns:
  File "/home/damon/Documents/Python/django-damon/local/lib/python2.7/site-packages/Django-1.6.4-py2.7.egg/django/core/urlresolvers.py", line 365, in url_patterns
    patterns = getattr(self.urlconf_module, "urlpatterns", self.urlconf_module)
  File "/home/damon/Documents/Python/django-damon/local/lib/python2.7/site-packages/Django-1.6.4-py2.7.egg/django/core/urlresolvers.py", line 360, in urlconf_module
    self._urlconf_module = import_module(self.urlconf_name)
  File "/home/damon/Documents/Python/django-damon/local/lib/python2.7/site-packages/Django-1.6.4-py2.7.egg/django/utils/importlib.py", line 40, in import_module
    __import__(name)
  File "/home/damon/Project/TenniSoda/TenniSoda/urls.py", line 4, in <module>
    admin.autodiscover()
  File "/home/damon/Documents/Python/django-damon/local/lib/python2.7/site-packages/Django-1.6.4-py2.7.egg/django/contrib/admin/__init__.py", line 29, in autodiscover
    import_module('%s.admin' % app)
  File "/home/damon/Documents/Python/django-damon/local/lib/python2.7/site-packages/Django-1.6.4-py2.7.egg/django/utils/importlib.py", line 40, in import_module
    __import__(name)
  File "/home/damon/Project/TenniSoda/account/admin.py", line 10, in <module>
    class UserCreationForm(forms.ModelForm):
  File "/home/damon/Documents/Python/django-damon/local/lib/python2.7/site-packages/Django-1.6.4-py2.7.egg/django/forms/models.py", line 261, in __new__
    raise TypeError(msg)
TypeError: UserCreationForm.Meta.fields cannot be a string. Did you mean to type: ('email',)?
2014-06-02 19:05:51,189 [WARNING] django.request: Not Found: /
2014-06-02 20:38:29,888 [ERROR] django.request: Internal Server Error: /account/register
Traceback (most recent call last):
  File "/home/damon/Documents/Python/django-damon/local/lib/python2.7/site-packages/Django-1.6.4-py2.7.egg/django/core/handlers/base.py", line 90, in get_response
    response = middleware_method(request)
  File "/home/damon/Documents/Python/django-damon/local/lib/python2.7/site-packages/Django-1.6.4-py2.7.egg/django/middleware/common.py", line 71, in process_request
    if (not urlresolvers.is_valid_path(request.path_info, urlconf) and
  File "/home/damon/Documents/Python/django-damon/local/lib/python2.7/site-packages/Django-1.6.4-py2.7.egg/django/core/urlresolvers.py", line 596, in is_valid_path
    resolve(path, urlconf)
  File "/home/damon/Documents/Python/django-damon/local/lib/python2.7/site-packages/Django-1.6.4-py2.7.egg/django/core/urlresolvers.py", line 476, in resolve
    return get_resolver(urlconf).resolve(path)
  File "/home/damon/Documents/Python/django-damon/local/lib/python2.7/site-packages/Django-1.6.4-py2.7.egg/django/core/urlresolvers.py", line 337, in resolve
    for pattern in self.url_patterns:
  File "/home/damon/Documents/Python/django-damon/local/lib/python2.7/site-packages/Django-1.6.4-py2.7.egg/django/core/urlresolvers.py", line 365, in url_patterns
    patterns = getattr(self.urlconf_module, "urlpatterns", self.urlconf_module)
  File "/home/damon/Documents/Python/django-damon/local/lib/python2.7/site-packages/Django-1.6.4-py2.7.egg/django/core/urlresolvers.py", line 360, in urlconf_module
    self._urlconf_module = import_module(self.urlconf_name)
  File "/home/damon/Documents/Python/django-damon/local/lib/python2.7/site-packages/Django-1.6.4-py2.7.egg/django/utils/importlib.py", line 40, in import_module
    __import__(name)
  File "/home/damon/Project/TenniSoda/TenniSoda/urls.py", line 12, in <module>
    url(r'^account/', include(account.urls)),
NameError: name 'account' is not defined
2014-06-02 20:59:37,879 [ERROR] django.request: Internal Server Error: /account/register
Traceback (most recent call last):
  File "/home/damon/Documents/Python/django-damon/local/lib/python2.7/site-packages/Django-1.6.4-py2.7.egg/django/core/handlers/base.py", line 90, in get_response
    response = middleware_method(request)
  File "/home/damon/Documents/Python/django-damon/local/lib/python2.7/site-packages/Django-1.6.4-py2.7.egg/django/middleware/common.py", line 72, in process_request
    urlresolvers.is_valid_path("%s/" % request.path_info, urlconf)):
  File "/home/damon/Documents/Python/django-damon/local/lib/python2.7/site-packages/Django-1.6.4-py2.7.egg/django/core/urlresolvers.py", line 596, in is_valid_path
    resolve(path, urlconf)
  File "/home/damon/Documents/Python/django-damon/local/lib/python2.7/site-packages/Django-1.6.4-py2.7.egg/django/core/urlresolvers.py", line 476, in resolve
    return get_resolver(urlconf).resolve(path)
  File "/home/damon/Documents/Python/django-damon/local/lib/python2.7/site-packages/Django-1.6.4-py2.7.egg/django/core/urlresolvers.py", line 339, in resolve
    sub_match = pattern.resolve(new_path)
  File "/home/damon/Documents/Python/django-damon/local/lib/python2.7/site-packages/Django-1.6.4-py2.7.egg/django/core/urlresolvers.py", line 339, in resolve
    sub_match = pattern.resolve(new_path)
  File "/home/damon/Documents/Python/django-damon/local/lib/python2.7/site-packages/Django-1.6.4-py2.7.egg/django/core/urlresolvers.py", line 223, in resolve
    return ResolverMatch(self.callback, args, kwargs, self.name)
  File "/home/damon/Documents/Python/django-damon/local/lib/python2.7/site-packages/Django-1.6.4-py2.7.egg/django/core/urlresolvers.py", line 230, in callback
    self._callback = get_callable(self._callback_str)
  File "/home/damon/Documents/Python/django-damon/local/lib/python2.7/site-packages/Django-1.6.4-py2.7.egg/django/utils/functional.py", line 32, in wrapper
    result = func(*args)
  File "/home/damon/Documents/Python/django-damon/local/lib/python2.7/site-packages/Django-1.6.4-py2.7.egg/django/core/urlresolvers.py", line 97, in get_callable
    mod = import_module(mod_name)
  File "/home/damon/Documents/Python/django-damon/local/lib/python2.7/site-packages/Django-1.6.4-py2.7.egg/django/utils/importlib.py", line 40, in import_module
    __import__(name)
  File "/home/damon/Project/TenniSoda/account/views.py", line 10, in <module>
    logr = loggin.getLogger(__name__)
NameError: name 'loggin' is not defined
2014-06-02 22:23:06,650 [WARNING] django.request: Not Found: /accounts/login/
2014-06-02 22:23:33,684 [WARNING] django.request: Not Found: /accounts/login/
2014-06-02 22:23:36,418 [WARNING] django.request: Not Found: /accounts/login/
2014-06-02 22:23:37,214 [WARNING] django.request: Not Found: /accounts/login/
2014-06-02 22:23:39,272 [WARNING] django.request: Not Found: /accounts/login/
2014-06-02 22:24:09,452 [ERROR] django.request: Internal Server Error: /account/welcome_user/
Traceback (most recent call last):
  File "/home/damon/Documents/Python/django-damon/local/lib/python2.7/site-packages/Django-1.6.4-py2.7.egg/django/core/handlers/base.py", line 114, in get_response
    response = wrapped_callback(request, *callback_args, **callback_kwargs)
  File "/home/damon/Documents/Python/django-damon/local/lib/python2.7/site-packages/Django-1.6.4-py2.7.egg/django/contrib/auth/decorators.py", line 22, in _wrapped_view
    return view_func(request, *args, **kwargs)
  File "/home/damon/Project/TenniSoda/account/views.py", line 57, in welcome_user
    username = request.user.emial.split('@')[0]
  File "/home/damon/Documents/Python/django-damon/local/lib/python2.7/site-packages/Django-1.6.4-py2.7.egg/django/utils/functional.py", line 214, in inner
    return func(self._wrapped, *args)
AttributeError: 'Account' object has no attribute 'emial'
2014-06-02 22:27:15,741 [WARNING] django.request: Not Found: /accounts/login/
2014-06-02 22:27:52,112 [ERROR] django.request: Internal Server Error: /account/logout/
Traceback (most recent call last):
  File "/home/damon/Documents/Python/django-damon/local/lib/python2.7/site-packages/Django-1.6.4-py2.7.egg/django/core/handlers/base.py", line 101, in get_response
    resolver_match = resolver.resolve(request.path_info)
  File "/home/damon/Documents/Python/django-damon/local/lib/python2.7/site-packages/Django-1.6.4-py2.7.egg/django/core/urlresolvers.py", line 339, in resolve
    sub_match = pattern.resolve(new_path)
  File "/home/damon/Documents/Python/django-damon/local/lib/python2.7/site-packages/Django-1.6.4-py2.7.egg/django/core/urlresolvers.py", line 339, in resolve
    sub_match = pattern.resolve(new_path)
  File "/home/damon/Documents/Python/django-damon/local/lib/python2.7/site-packages/Django-1.6.4-py2.7.egg/django/core/urlresolvers.py", line 223, in resolve
    return ResolverMatch(self.callback, args, kwargs, self.name)
  File "/home/damon/Documents/Python/django-damon/local/lib/python2.7/site-packages/Django-1.6.4-py2.7.egg/django/core/urlresolvers.py", line 230, in callback
    self._callback = get_callable(self._callback_str)
  File "/home/damon/Documents/Python/django-damon/local/lib/python2.7/site-packages/Django-1.6.4-py2.7.egg/django/utils/functional.py", line 32, in wrapper
    result = func(*args)
  File "/home/damon/Documents/Python/django-damon/local/lib/python2.7/site-packages/Django-1.6.4-py2.7.egg/django/core/urlresolvers.py", line 118, in get_callable
    (lookup_view, mod_name))
ViewDoesNotExist: Could not import account.views.logout. View does not exist in module account.views.
2014-06-02 22:35:31,086 [WARNING] django.request: Forbidden (CSRF token missing or incorrect.): /account/auth/
2014-06-02 22:35:45,179 [WARNING] django.request: Forbidden (CSRF token missing or incorrect.): /account/auth/
2014-06-02 22:35:52,113 [WARNING] django.request: Forbidden (CSRF token missing or incorrect.): /account/auth/
2014-06-02 22:37:02,143 [WARNING] django.request: Forbidden (CSRF token missing or incorrect.): /account/auth/
2014-06-02 22:38:08,249 [WARNING] django.request: Not Found: /account/loging
2014-06-02 22:40:08,448 [WARNING] django.request: Forbidden (CSRF token missing or incorrect.): /account/auth/
2014-06-03 17:10:31,842 [WARNING] django.request: Not Found: /
2014-06-03 17:11:58,664 [WARNING] django.request: Not Found: /accout
2014-06-03 17:12:09,058 [WARNING] django.request: Not Found: /account
2014-06-03 17:12:19,877 [WARNING] django.request: Not Found: /account/
2014-06-03 17:27:31,578 [WARNING] django.request: Not Found: /account/
2014-06-03 17:27:40,114 [ERROR] django.request: Internal Server Error: /account/register/
Traceback (most recent call last):
  File "/Users/haochenwu/Documents/TimmyDjango/lib/python2.7/site-packages/Django-1.6.4-py2.7.egg/django/core/handlers/base.py", line 114, in get_response
    response = wrapped_callback(request, *callback_args, **callback_kwargs)
  File "/Users/haochenwu/Documents/TenniSoda/account/views.py", line 34, in register_user
    return render_to_response('register.html', args)
  File "/Users/haochenwu/Documents/TimmyDjango/lib/python2.7/site-packages/Django-1.6.4-py2.7.egg/django/shortcuts/__init__.py", line 29, in render_to_response
    return HttpResponse(loader.render_to_string(*args, **kwargs), **httpresponse_kwargs)
  File "/Users/haochenwu/Documents/TimmyDjango/lib/python2.7/site-packages/Django-1.6.4-py2.7.egg/django/template/loader.py", line 164, in render_to_string
    return t.render(Context(dictionary))
  File "/Users/haochenwu/Documents/TimmyDjango/lib/python2.7/site-packages/Django-1.6.4-py2.7.egg/django/template/base.py", line 140, in render
    return self._render(context)
  File "/Users/haochenwu/Documents/TimmyDjango/lib/python2.7/site-packages/Django-1.6.4-py2.7.egg/django/template/base.py", line 134, in _render
    return self.nodelist.render(context)
  File "/Users/haochenwu/Documents/TimmyDjango/lib/python2.7/site-packages/Django-1.6.4-py2.7.egg/django/template/base.py", line 840, in render
    bit = self.render_node(node, context)
  File "/Users/haochenwu/Documents/TimmyDjango/lib/python2.7/site-packages/Django-1.6.4-py2.7.egg/django/template/debug.py", line 78, in render_node
    return node.render(context)
  File "/Users/haochenwu/Documents/TimmyDjango/lib/python2.7/site-packages/Django-1.6.4-py2.7.egg/django/template/loader_tags.py", line 101, in render
    compiled_parent = self.get_parent(context)
  File "/Users/haochenwu/Documents/TimmyDjango/lib/python2.7/site-packages/Django-1.6.4-py2.7.egg/django/template/loader_tags.py", line 98, in get_parent
    return get_template(parent)
  File "/Users/haochenwu/Documents/TimmyDjango/lib/python2.7/site-packages/Django-1.6.4-py2.7.egg/django/template/loader.py", line 138, in get_template
    template, origin = find_template(template_name)
  File "/Users/haochenwu/Documents/TimmyDjango/lib/python2.7/site-packages/Django-1.6.4-py2.7.egg/django/template/loader.py", line 131, in find_template
    raise TemplateDoesNotExist(name)
TemplateDoesNotExist: base.html
